2022-03-20 14:22:35,113 - ERROR - Exception occured
Traceback (most recent call last):
  File "C:\Users\aisha\PycharmProjects\PriceBasket\main.py", line 81, in display_inventory
    cart_products = get_cart_products()
  File "C:\Users\aisha\PycharmProjects\PriceBasket\main.py", line 70, in get_cart_products
    with open('Cache/cart/cartProducts.pkl', 'rb') as in_file:
FileNotFoundError: [Errno 2] No such file or directory: 'Cache/cart/cartProducts.pkl'
2022-03-20 14:23:38,442 - ERROR - Exception occured
Traceback (most recent call last):
  File "C:\Users\aisha\PycharmProjects\PriceBasket\main.py", line 81, in display_inventory
    cart_products = get_cart_products()
  File "C:\Users\aisha\PycharmProjects\PriceBasket\main.py", line 70, in get_cart_products
    with open('Cache/cart/cartProducts.pkl', 'rb') as in_file:
FileNotFoundError: [Errno 2] No such file or directory: 'Cache/cart/cartProducts.pkl'
2022-03-20 14:23:57,365 - ERROR - Exception occured
Traceback (most recent call last):
  File "C:\Users\aisha\PycharmProjects\PriceBasket\main.py", line 81, in display_inventory
    cart_products = get_cart_products()
  File "C:\Users\aisha\PycharmProjects\PriceBasket\main.py", line 70, in get_cart_products
    with open('Cache/cart/cartProducts.pkl', 'rb') as in_file:
FileNotFoundError: [Errno 2] No such file or directory: 'Cache/cart/cartProducts.pkl'
2022-03-20 14:38:49,118 - ERROR - Exception occured
Traceback (most recent call last):
  File "C:\Users\aisha\PycharmProjects\PriceBasket\main.py", line 81, in display_inventory
    cart_products = get_cart_products()
  File "C:\Users\aisha\PycharmProjects\PriceBasket\main.py", line 70, in get_cart_products
    with open('Cache/cart/cartProducts.pkl', 'rb') as in_file:
FileNotFoundError: [Errno 2] No such file or directory: 'Cache/cart/cartProducts.pkl'
